ERROR:root:Logging with exception info
Traceback (most recent call last):
  File "c:\Users\student\Desktop\bpyjpmcintro\EXAMPLES\logging_exception.py", line 11, in <module>
    result = i/0
             ~^~
ZeroDivisionError: division by zero
ERROR:root:Logging with exception info
Traceback (most recent call last):
  File "c:\Users\student\Desktop\bpyjpmcintro\EXAMPLES\logging_exception.py", line 11, in <module>
    result = i/0
             ~^~
ZeroDivisionError: division by zero
ERROR:root:Logging with exception info
Traceback (most recent call last):
  File "c:\Users\student\Desktop\bpyjpmcintro\EXAMPLES\logging_exception.py", line 11, in <module>
    result = i/0
             ~^~
ZeroDivisionError: division by zero
ERROR:root:Logging with exception info
Traceback (most recent call last):
  File "c:\Users\student\Desktop\bpyjpmcintro\EXAMPLES\logging_exception.py", line 11, in <module>
    result = i/0
             ~^~
ZeroDivisionError: division by zero
ERROR:root:Logging with exception info
Traceback (most recent call last):
  File "c:\Users\student\Desktop\bpyjpmcintro\EXAMPLES\logging_exception.py", line 11, in <module>
    result = i/0
             ~^~
ZeroDivisionError: division by zero
ERROR:root:Logging with exception info
Traceback (most recent call last):
  File "c:\Users\student\Desktop\bpyjpmcintro\EXAMPLES\logging_exception.py", line 11, in <module>
    result = i/0
             ~^~
ZeroDivisionError: division by zero
ERROR:root:Logging with exception info
Traceback (most recent call last):
  File "c:\Users\student\Desktop\bpyjpmcintro\EXAMPLES\logging_exception.py", line 11, in <module>
    result = i/0
             ~^~
ZeroDivisionError: division by zero
ERROR:root:Logging with exception info
Traceback (most recent call last):
  File "c:\Users\student\Desktop\bpyjpmcintro\EXAMPLES\logging_exception.py", line 11, in <module>
    result = i/0
             ~^~
ZeroDivisionError: division by zero
ERROR:root:Logging with exception info
Traceback (most recent call last):
  File "c:\Users\student\Desktop\bpyjpmcintro\EXAMPLES\logging_exception.py", line 11, in <module>
    result = i/0
             ~^~
ZeroDivisionError: division by zero
ERROR:root:Logging with exception info
Traceback (most recent call last):
  File "c:\Users\student\Desktop\bpyjpmcintro\EXAMPLES\logging_exception.py", line 11, in <module>
    result = i/0
             ~^~
ZeroDivisionError: division by zero
ERROR:root:Logging with exception info
Traceback (most recent call last):
  File "c:\Users\student\Desktop\bpyjpmcintro\EXAMPLES\logging_exception.py", line 11, in <module>
    result = i/0
             ~^~
ZeroDivisionError: division by zero
ERROR:root:Logging with exception info
Traceback (most recent call last):
  File "c:\Users\student\Desktop\bpyjpmcintro\EXAMPLES\logging_exception.py", line 11, in <module>
    result = i/0
             ~^~
ZeroDivisionError: division by zero
ERROR:root:Logging with exception info
Traceback (most recent call last):
  File "c:\Users\student\Desktop\bpyjpmcintro\EXAMPLES\logging_exception.py", line 11, in <module>
    result = i/0
             ~^~
ZeroDivisionError: division by zero
ERROR:root:Logging with exception info
Traceback (most recent call last):
  File "c:\Users\student\Desktop\bpyjpmcintro\EXAMPLES\logging_exception.py", line 11, in <module>
    result = i/0
             ~^~
ZeroDivisionError: division by zero
ERROR:root:Logging with exception info
Traceback (most recent call last):
  File "c:\Users\student\Desktop\bpyjpmcintro\EXAMPLES\logging_exception.py", line 11, in <module>
    result = i/0
             ~^~
ZeroDivisionError: division by zero
